<?xml version="1.0" ?>

<sdf version="1.5">
    <model name='sam_bot'>
    <link name='base_link'>
        <inertial>
        <pose>0.007054 0 0.013988 1.5708 -0 1.5708</pose>
        <mass>1.1659999999999999</mass>
        <inertia>
            <ixx>0.022766700000000001</ixx>
            <ixy>-5.61451e-20</ixy>
            <ixz>-4.6963199999999997e-19</ixz>
            <iyy>0.026375099999999999</iyy>
            <iyz>-0.000198199</iyz>
            <izz>0.0144172</izz>
        </inertia>
        </inertial>
        <collision name='base_link_collision'>
        <pose>0 0 0 0 0 0</pose>
        <geometry>
            <box>
            <size>0.42 0.31 0.18</size>
            </box>
        </geometry>
        <surface>
            <friction>
            <ode/>
            </friction>
            <bounce/>
            <contact/>
        </surface>
        </collision>
        <collision name='base_link_fixed_joint_lump__camera_link_collision_1'>
        <pose>0.215 0 0.05 0 0 0</pose>
        <geometry>
            <box>
            <size>0.015 0.13 0.022</size>
            </box>
        </geometry>
        <surface>
            <contact>
            <ode/>
            </contact>
            <friction>
            <ode/>
            </friction>
            <bounce/>
        </surface>
        </collision>
        <collision name='base_link_fixed_joint_lump__front_caster_collision_2'>
        <pose>0.14 0 -0.09 0 0 0</pose>
        <geometry>
            <sphere>
            <radius>0.060000000000000032</radius>
            </sphere>
        </geometry>
        <surface>
            <friction>
            <ode/>
            </friction>
            <bounce/>
            <contact/>
        </surface>
        </collision>
        <collision name='base_link_fixed_joint_lump__imu_link_collision_3'>
        <pose>0 0 0.01 0 0 0</pose>
        <geometry>
            <box>
            <size>0.1 0.1 0.1</size>
            </box>
        </geometry>
        <surface>
            <contact>
            <ode/>
            </contact>
            <friction>
            <ode/>
            </friction>
            <bounce/>
        </surface>
        </collision>
        <collision name='base_link_fixed_joint_lump__lidar_link_collision_4'>
        <pose>0 0 0.12 0 0 0</pose>
        <geometry>
            <cylinder>
            <length>0.055</length>
            <radius>0.050799999999999998</radius>
            </cylinder>
        </geometry>
        <surface>
            <contact>
            <ode/>
            </contact>
            <friction>
            <ode/>
            </friction>
            <bounce/>
        </surface>
        </collision>
        <visual name='base_link_visual'>
        <pose>0 0 0 0 0 0</pose>
        <geometry>
            <box>
            <size>0.42 0.31 0.18</size>
            </box>
        </geometry>
        <material>
            <diffuse>0.1125 0.375 0.575 1</diffuse>
            <ambient>0.1125 0.375 0.575 1</ambient>
        </material>
        </visual>
        <visual name='base_link_fixed_joint_lump__camera_link_visual_1'>
        <pose>0.215 0 0.05 0 0 0</pose>
        <geometry>
            <box>
            <size>0.015 0.13 0.022</size>
            </box>
        </geometry>
        <material>
            <diffuse>0.1375 0.4625 0.7 1</diffuse>
            <ambient>0.1375 0.4625 0.7 1</ambient>
        </material>
        </visual>
        <visual name='base_link_fixed_joint_lump__front_caster_visual_2'>
        <pose>0.14 0 -0.09 0 0 0</pose>
        <geometry>
            <sphere>
            <radius>0.060000000000000032</radius>
            </sphere>
        </geometry>
        <material>
            <diffuse>0.1125 0.375 0.575 1</diffuse>
            <ambient>0.1125 0.375 0.575 1</ambient>
        </material>
        </visual>
        <visual name='base_link_fixed_joint_lump__imu_link_visual_3'>
        <pose>0 0 0.01 0 0 0</pose>
        <geometry>
            <box>
            <size>0.1 0.1 0.1</size>
            </box>
        </geometry>
        </visual>
        <visual name='base_link_fixed_joint_lump__lidar_link_visual_4'>
        <pose>0 0 0.12 0 0 0</pose>
        <geometry>
            <cylinder>
            <length>0.055</length>
            <radius>0.050799999999999998</radius>
            </cylinder>
        </geometry>
        <material>
            <diffuse>0.1375 0.4625 0.7 1</diffuse>
            <ambient>0.1375 0.4625 0.7 1</ambient>
        </material>
        </visual>
        <sensor name='robot_cam' type='camera'>
        <pose>0.215 0 0.05 0 -0 0</pose>
        <topic>robot_cam</topic>
        <update_rate>30</update_rate>
        <enable_metrics>true</enable_metrics>
        <camera name='__default__'>
            <pose>0 0 0 0 -0 0</pose>
            <horizontal_fov>1.0469999999999999</horizontal_fov>
            <image>
            <width>320</width>
            <height>240</height>
            <format>RGB_INT8</format>
            <anti_aliasing>4</anti_aliasing>
            </image>
            <camera_info_topic>__default__</camera_info_topic>
            <trigger_topic></trigger_topic>
            <triggered>false</triggered>
            <clip>
            <near>0.10000000000000001</near>
            <far>100</far>
            </clip>
            <save enabled='false'>
            <path>__default__</path>
            </save>
            <visibility_mask>4294967295</visibility_mask>
            <noise>
            <type>none</type>
            <mean>0</mean>
            <stddev>0</stddev>
            </noise>
            <distortion>
            <k1>0</k1>
            <k2>0</k2>
            <k3>0</k3>
            <p1>0</p1>
            <p2>0</p2>
            <center>0.5 0.5</center>
            </distortion>
            <lens>
            <type>stereographic</type>
            <scale_to_hfov>true</scale_to_hfov>
            <cutoff_angle>1.5708</cutoff_angle>
            <env_texture_size>256</env_texture_size>
            </lens>
            <optical_frame_id></optical_frame_id>
        </camera>
        </sensor>
        <sensor name='imu_sensor' type='imu'>
        <pose>0 0 0.01 0 -0 0</pose>
        <topic>imu</topic>
        <update_rate>100</update_rate>
        <enable_metrics>false</enable_metrics>
        <imu>
            <orientation_reference_frame>
            <localization>CUSTOM</localization>
            <custom_rpy>0 0 0</custom_rpy>
            <grav_dir_x>1 0 0</grav_dir_x>
            </orientation_reference_frame>
            <angular_velocity>
            <x>
                <noise type='gaussian'>
                <mean>0</mean>
                <stddev>0.00020000000000000001</stddev>
                <bias_mean>7.5000000000000002e-06</bias_mean>
                <bias_stddev>7.9999999999999996e-07</bias_stddev>
                <dynamic_bias_stddev>0</dynamic_bias_stddev>
                <dynamic_bias_correlation_time>0</dynamic_bias_correlation_time>
                <precision>0</precision>
                </noise>
            </x>
            <y>
                <noise type='gaussian'>
                <mean>0</mean>
                <stddev>0.00020000000000000001</stddev>
                <bias_mean>7.5000000000000002e-06</bias_mean>
                <bias_stddev>7.9999999999999996e-07</bias_stddev>
                <dynamic_bias_stddev>0</dynamic_bias_stddev>
                <dynamic_bias_correlation_time>0</dynamic_bias_correlation_time>
                <precision>0</precision>
                </noise>
            </y>
            <z>
                <noise type='gaussian'>
                <mean>0</mean>
                <stddev>0.00020000000000000001</stddev>
                <bias_mean>7.5000000000000002e-06</bias_mean>
                <bias_stddev>7.9999999999999996e-07</bias_stddev>
                <dynamic_bias_stddev>0</dynamic_bias_stddev>
                <dynamic_bias_correlation_time>0</dynamic_bias_correlation_time>
                <precision>0</precision>
                </noise>
            </z>
            </angular_velocity>
            <linear_acceleration>
            <x>
                <noise type='gaussian'>
                <mean>0</mean>
                <stddev>0.017000000000000001</stddev>
                <bias_mean>0.10000000000000001</bias_mean>
                <bias_stddev>0.001</bias_stddev>
                <dynamic_bias_stddev>0</dynamic_bias_stddev>
                <dynamic_bias_correlation_time>0</dynamic_bias_correlation_time>
                <precision>0</precision>
                </noise>
            </x>
            <y>
                <noise type='gaussian'>
                <mean>0</mean>
                <stddev>0.017000000000000001</stddev>
                <bias_mean>0.10000000000000001</bias_mean>
                <bias_stddev>0.001</bias_stddev>
                <dynamic_bias_stddev>0</dynamic_bias_stddev>
                <dynamic_bias_correlation_time>0</dynamic_bias_correlation_time>
                <precision>0</precision>
                </noise>
            </y>
            <z>
                <noise type='gaussian'>
                <mean>0</mean>
                <stddev>0.017000000000000001</stddev>
                <bias_mean>0.10000000000000001</bias_mean>
                <bias_stddev>0.001</bias_stddev>
                <dynamic_bias_stddev>0</dynamic_bias_stddev>
                <dynamic_bias_correlation_time>0</dynamic_bias_correlation_time>
                <precision>0</precision>
                </noise>
            </z>
            </linear_acceleration>
            <enable_orientation>true</enable_orientation>
        </imu>
        <plugin name='ignition::gazebo::systems::Imu' filename='ignition-gazebo-imu-system'/>
        </sensor>
        <sensor name='lidar' type='gpu_lidar'>
        <pose>0 0 0.12 0 -0 0</pose>
        <topic>scan</topic>
        <update_rate>5</update_rate>
        <enable_metrics>false</enable_metrics>
        <lidar>
            <scan>
            <horizontal>
                <samples>360</samples>
                <resolution>1</resolution>
                <min_angle>0</min_angle>
                <max_angle>6.2800000000000002</max_angle>
            </horizontal>
            <vertical>
                <samples>1</samples>
                <min_angle>-0.261799</min_angle>
                <max_angle>0.261799</max_angle>
                <resolution>1</resolution>
            </vertical>
            </scan>
            <range>
            <min>0.12</min>
            <max>100</max>
            <resolution>0.014999999999999999</resolution>
            </range>
            <noise>
            <type>gaussian</type>
            <mean>0</mean>
            <stddev>0.01</stddev>
            </noise>
            <visibility_mask>4294967295</visibility_mask>
        </lidar>
        </sensor>
        <pose>0 0 0 0 -0 0</pose>
        <enable_wind>false</enable_wind>
    </link>
    <joint name='drivewhl_l_joint' type='revolute'>
        <pose>0 0 0 0 -0 0</pose>
        <parent>base_link</parent>
        <child>drivewhl_l_link</child>
        <axis>
        <xyz>0 1 0</xyz>
        <limit>
            <lower>-10000000000000000</lower>
            <upper>10000000000000000</upper>
            <effort>inf</effort>
            <velocity>inf</velocity>
            <stiffness>100000000</stiffness>
            <dissipation>1</dissipation>
        </limit>
        <dynamics>
            <spring_reference>0</spring_reference>
            <spring_stiffness>0</spring_stiffness>
            <damping>0.20000000000000001</damping>
            <friction>0</friction>
        </dynamics>
        </axis>
    </joint>
    <link name='drivewhl_l_link'>
        <pose>-0.12 0.18 -0.05 0 -1e-05 0</pose>
        <inertial>
        <pose>0 0 0 1.5708 -0 0</pose>
        <mass>2.5</mass>
        <inertia>
            <ixx>0.0065833300000000001</ixx>
            <ixy>0</ixy>
            <ixz>0</ixz>
            <iyy>0.0065833300000000001</iyy>
            <iyz>0</iyz>
            <izz>0.012500000000000001</izz>
        </inertia>
        </inertial>
        <collision name='drivewhl_l_link_collision'>
        <pose>0 0 0 1.570796326794896 0 0</pose>
        <geometry>
            <cylinder>
            <length>0.040000000000000001</length>
            <radius>0.10000000000000001</radius>
            </cylinder>
        </geometry>
        <surface>
            <friction>
            <ode/>
            </friction>
            <bounce/>
            <contact/>
        </surface>
        </collision>
        <visual name='drivewhl_l_link_visual'>
        <pose>0 0 0 1.570796326794896 0 0</pose>
        <geometry>
            <cylinder>
            <length>0.040000000000000001</length>
            <radius>0.10000000000000001</radius>
            </cylinder>
        </geometry>
        <material>
            <diffuse>0.1375 0.4625 0.7 1</diffuse>
            <ambient>0.1375 0.4625 0.7 1</ambient>
        </material>
        </visual>
        <enable_wind>false</enable_wind>
    </link>
    <joint name='drivewhl_r_joint' type='revolute'>
        <pose>0 0 0 0 -0 0</pose>
        <parent>base_link</parent>
        <child>drivewhl_r_link</child>
        <axis>
        <xyz>0 1 0</xyz>
        <limit>
            <lower>-10000000000000000</lower>
            <upper>10000000000000000</upper>
            <effort>inf</effort>
            <velocity>inf</velocity>
            <stiffness>100000000</stiffness>
            <dissipation>1</dissipation>
        </limit>
        <dynamics>
            <spring_reference>0</spring_reference>
            <spring_stiffness>0</spring_stiffness>
            <damping>0.20000000000000001</damping>
            <friction>0</friction>
        </dynamics>
        </axis>
    </joint>
    <link name='drivewhl_r_link'>
        <pose>-0.12 -0.18 -0.05 0 -1e-05 0</pose>
        <inertial>
        <pose>0 0 0 1.5708 -0 0</pose>
        <mass>2.5</mass>
        <inertia>
            <ixx>0.0065833300000000001</ixx>
            <ixy>0</ixy>
            <ixz>0</ixz>
            <iyy>0.0065833300000000001</iyy>
            <iyz>0</iyz>
            <izz>0.012500000000000001</izz>
        </inertia>
        </inertial>
        <collision name='drivewhl_r_link_collision'>
        <pose>0 0 0 1.570796326794896 0 0</pose>
        <geometry>
            <cylinder>
            <length>0.040000000000000001</length>
            <radius>0.10000000000000001</radius>
            </cylinder>
        </geometry>
        <surface>
            <friction>
            <ode/>
            </friction>
            <bounce/>
            <contact/>
        </surface>
        </collision>
        <visual name='drivewhl_r_link_visual'>
        <pose>0 0 0 1.570796326794896 0 0</pose>
        <geometry>
            <cylinder>
            <length>0.040000000000000001</length>
            <radius>0.10000000000000001</radius>
            </cylinder>
        </geometry>
        <material>
            <diffuse>0.1375 0.4625 0.7 1</diffuse>
            <ambient>0.1375 0.4625 0.7 1</ambient>
        </material>
        </visual>
        <enable_wind>false</enable_wind>
    </link>
    <plugin name='ign_ros2_control::IgnitionROS2ControlPlugin' filename='ign_ros2_control-system'>
        <parameters>/home/ibrahim/code/ign_sim_ws/install/sam_bot_nav2_gz/share/sam_bot_nav2_gz/config/diff_drive_controller_velocity.yaml</parameters>
    </plugin>
    <frame name='base_joint' attached_to='base_link'>
        <pose>0 0 -0.15 0 -0 0</pose>
    </frame>
    <frame name='base_footprint' attached_to='base_joint'/>
    <frame name='camera_frame_joint' attached_to='camera_link'>
        <pose>0 0 0 -1.5708 -0 -1.5708</pose>
    </frame>
    <frame name='camera_frame' attached_to='camera_frame_joint'/>
    <frame name='camera_joint' attached_to='base_link'>
        <pose>0.215 0 0.05 0 -0 0</pose>
    </frame>
    <frame name='camera_link' attached_to='camera_joint'/>
    <frame name='caster_joint' attached_to='base_link'>
        <pose>0.14 0 -0.09 0 -0 0</pose>
    </frame>
    <frame name='front_caster' attached_to='caster_joint'/>
    <frame name='imu_joint' attached_to='base_link'>
        <pose>0 0 0.01 0 -0 0</pose>
    </frame>
    <frame name='imu_link' attached_to='imu_joint'/>
    <frame name='lidar_joint' attached_to='base_link'>
        <pose>0 0 0.12 0 -0 0</pose>
    </frame>
    <frame name='lidar_link' attached_to='lidar_joint'/>
    <pose>-5.74164 11.1138 0.15 -0 0 -0</pose>
    <static>false</static>
    <self_collide>false</self_collide>
    </model>

</sdf>