<?xml version="1.0"?>
<robot name="rover_2wd"
  xmlns:xacro="http://ros.org/wiki/xacro">

    <!-- Robot Parameters -->
    <xacro:property name="wheel_z_offset" value="0.020" />
    <xacro:property name="wheel_x_offset" value="0.1415" />
    <xacro:property name="wheel_y_offset" value="0.18" />
    <xacro:property name="castor_x_offset" value="0.07" />
    <xacro:property name="castor_y_offset" value="0.169" />
    <xacro:property name="castor_z_offset" value="-0.05" />
    <xacro:property name="wheel_mass" value="1.25" /> 
    <xacro:property name="castor_mass" value="0.2" /> 
    <xacro:property name="castor_housing_mass" value="0.35" /> 
    <xacro:property name="chassis_mass" value="6.5" />

    <!-- Define some commonly used intertial properties  -->
    <xacro:macro name="box_inertia" params="m w h d">
      <inertial>
        <origin xyz="0 0 0" rpy="${pi/2} 0 ${pi/2}"/>
        <mass value="${m}"/>
        <inertia ixx="${(m/12) * (h*h + d*d)}" ixy="0.0" ixz="0.0" iyy="${(m/12) * (w*w + d*d)}" iyz="0.0" izz="${(m/12) * (w*w + h*h)}"/>
      </inertial>
    </xacro:macro>

    <xacro:macro name="cylinder_inertia" params="m r h">
      <inertial>
        <origin xyz="0 0 0" rpy="${pi/2} 0 0" />
        <mass value="${m}"/>
        <inertia ixx="${(m/12) * (3*r*r + h*h)}" ixy = "0" ixz = "0" iyy="${(m/12) * (3*r*r + h*h)}" iyz = "0" izz="${(m/2) * (r*r)}"/>
      </inertial>
    </xacro:macro>

    <xacro:macro name="sphere_inertia" params="m r">
      <inertial>
        <mass value="${m}"/>
        <inertia ixx="${(2/5) * m * (r*r)}" ixy="0.0" ixz="0.0" iyy="${(2/5) * m * (r*r)}" iyz="0.0" izz="${(2/5) * m * (r*r)}"/>
      </inertial>
    </xacro:macro>

    <!-- Part Includes - Payload, Sensors, Etc.. -->
    <!-- Comment or Uncomment any of these to add them to the dev payload -->
    <!-- You can always link them elsewhere if you wish by editing accessories/<sensor>.urdf -->
    <xacro:property name="payload_z_offset" value="0.096"/>
    <xacro:include filename="$(find nav2_gazebo)/description/rover_dev_payload.urdf"/>
    <!-- xacro:include filename="$(find nav2_gazebo)/description/lidar.urdf"/ -->
    <xacro:include filename="$(find nav2_gazebo)/description/imu.urdf"/>

    <!-- Robot Definition -->
    <link name="base_link" />

    <!-- Robot Footprint -->
    <link name="base_footprint"/>

    <joint name="base_joint" type="fixed">
      <parent link="base_link"/>
      <child link="base_footprint"/>
      <origin xyz="0.0 0.0 -0.15" rpy="0 0 0"/>
    </joint>

    <link name="chassis_link">
        <visual name="body_vis">
            <origin xyz="0 0 0" rpy="1.57 -0 1.57" />
            <geometry>
                <mesh filename="file://$(find nav2_gazebo)/models/rover/rover_2wd_core.dae"/>
            </geometry>
        </visual>
        <collision name="body_col">
            <origin xyz="0 0 0" rpy="1.57 -0 1.57" />
            <geometry>
                <mesh filename="file://$(find nav2_gazebo)/models/rover/rover_2wd_core.dae"/>
            </geometry>
        </collision>

        <inertial>
            <origin xyz="0 0 0" rpy="0 0 0"/>
            <mass value="${chassis_mass}" />
            <inertia ixx="0.028064" ixy="0.0"  ixz="0.0" iyy="0.08226" iyz="0.0" izz="0.10258" />
        </inertial>
    </link>

    <joint name="base_to_chassis" type="fixed">
        <parent link="base_link"/>
        <child link="chassis_link"/>
        <origin xyz="0 0 0.125"/>
    </joint>

    <link name="fr_wheel_link">
        <visual>
            <origin xyz="0 0 0" rpy="-1.57 0 0" />
            <geometry>
                <mesh filename="file://$(find nav2_gazebo)/models/rover/pro_tire.dae"/>
            </geometry>
        </visual>

        <collision>
            <origin xyz="0 0 0" rpy="-1.57 0 0" />
            <geometry>
                <mesh filename="file://$(find nav2_gazebo)/models/rover/pro_tire.dae"/>
            </geometry>
        </collision>

        <inertial>
            <origin xyz="0 0 0" rpy="0 0 0" />
            <mass value="${wheel_mass}" />
            <inertia ixx="0.005645" ixy="0.0"  ixz="0.0" iyy= "0.01008" iyz="0.0" izz="0.005645"/>
        </inertial>
        <mu>5.0</mu>
    </link>
    <joint name="fr_wheel_to_chassis" type="continuous">
        <parent link="chassis_link"/>
        <child link="fr_wheel_link"/>
        <axis xyz="0 1 0"/>
        <origin xyz="${wheel_x_offset} ${-wheel_y_offset} 0" rpy="0 0 0"/>
    </joint>

    <link name="fl_wheel_link">
        <visual>
            <origin xyz="0 0 0" rpy="1.57 0 0" />
            <geometry>
                <mesh filename="file://$(find nav2_gazebo)/models/rover/pro_tire.dae"/>
            </geometry>
        </visual>

        <collision>
            <origin xyz="0 0 0" rpy="1.57 0 0" />
            <geometry>
                <mesh filename="file://$(find nav2_gazebo)/models/rover/pro_tire.dae"/>
            </geometry>
        </collision>

        <inertial>
            <origin xyz="0 0 0" rpy="0 0 0" />
            <mass value="${wheel_mass}" />
            <inertia ixx="0.005645" ixy="0.0"  ixz="0.0" iyy= "0.01008" iyz="0.0" izz="0.005645"/>
        </inertial>
        <mu>5.0</mu>
    </link>
    <joint name="fl_wheel_to_chassis" type="continuous">
        <parent link="chassis_link"/>
        <child link="fl_wheel_link"/>
        <axis xyz="0 1 0"/>
        <origin xyz="${wheel_x_offset} ${wheel_y_offset} 0" rpy="0 0 0"/>
    </joint>

    <link name="rl_castor_housing_link">
        <visual>
            <origin xyz="0 0 0" rpy="1.57 0 1.57" />
            <geometry>
                <mesh filename="file://$(find nav2_gazebo)/models/rover/castor_housing.dae"/>
            </geometry>
        </visual>

        <collision>
            <origin xyz="0 0 0" rpy="1.57 0 1.57" />
            <geometry>
                <mesh filename="file://$(find nav2_gazebo)/models/rover/castor_housing.dae"/>
            </geometry>
        </collision>

        <inertial>
            <origin xyz="0 0 0" rpy="0 0 0" />
            <mass value="${castor_housing_mass}" />
            <inertia ixx="0.0003187" ixy="0.0"  ixz="0.0" iyy="0.0003187" iyz="0.0" izz="0.0001764" />
        </inertial>
        <mu>5.0</mu>
    </link>
    <joint name="rl_ch_to_chassis" type="continuous">
        <parent link="chassis_link"/>
        <child link="rl_castor_housing_link"/>
        <axis xyz="0 0 1"/>
        <origin xyz="${-wheel_x_offset - castor_x_offset} ${castor_y_offset + 0.0025} ${castor_z_offset}" rpy="0 0 0"/>
    </joint>
    <link name="rl_castor_link">
        <visual>
            <origin xyz="0 0 0" rpy="1.57 0 1.57" />
            <geometry>
                <mesh filename="file://$(find nav2_gazebo)/models/rover/castor.dae"/>
            </geometry>
        </visual>

        <collision>
            <origin xyz="0 0 0" rpy="1.57 0 1.57" />
            <geometry>
                <mesh filename="file://$(find nav2_gazebo)/models/rover/castor.dae"/>
            </geometry>
        </collision>

        <inertial>
            <origin xyz="0 0 0" rpy="0 0 0" />
            <mass value="${castor_mass}" />
            <inertia ixx="0.00013978" ixy="0.0"  ixz="0.0" iyy="0.00025806" iyz="0.0" izz="0.00013978" />
        </inertial>
        <mu>5.0</mu>
    </link>
    <joint name="rl_castor_to_chassis" type="continuous">
        <parent link="rl_castor_housing_link"/>
        <child link="rl_castor_link"/>
        <axis xyz="0 1 0"/>
        <origin xyz="-0.031 0 -0.027" rpy="0 0 0"/>
    </joint>


    <link name="rr_castor_housing_link">
        <visual>
            <origin xyz="0 0 0" rpy="1.57 0 1.57" />
            <geometry>
                <mesh filename="file://$(find nav2_gazebo)/models/rover/castor_housing.dae"/>
            </geometry>
        </visual>

        <collision>
            <origin xyz="0 0 0" rpy="1.57 0 1.57" />
            <geometry>
                <mesh filename="file://$(find nav2_gazebo)/models/rover/castor_housing.dae"/>
            </geometry>
        </collision>

        <inertial>
            <origin xyz="0 0 0" rpy="0 0 0" />
            <mass value="${castor_housing_mass}" />
            <inertia ixx="0.0003187" ixy="0.0"  ixz="0.0" iyy="0.0003187" iyz="0.0" izz="0.0001764" />
        </inertial>
        <mu>5.0</mu>
    </link>
    <joint name="rr_ch_to_chassis" type="continuous">
        <parent link="chassis_link"/>
        <child link="rr_castor_housing_link"/>
        <axis xyz="0 0 1"/>
        <origin xyz="${-wheel_x_offset - castor_x_offset} ${-castor_y_offset} ${castor_z_offset}" rpy="0 0 0"/>
    </joint>
    <link name="rr_castor_link">
        <visual>
            <origin xyz="0 0 0" rpy="1.57 0 1.57" />
            <geometry>
                <mesh filename="file://$(find nav2_gazebo)/models/rover/castor.dae"/>
            </geometry>
        </visual>

        <collision>
            <origin xyz="0 0 0" rpy="1.57 0 1.57" />
            <geometry>
                <mesh filename="file://$(find nav2_gazebo)/models/rover/castor.dae"/>
            </geometry>
        </collision>

        <inertial>
            <origin xyz="0 0 0" rpy="0 0 0" />
            <mass value="${castor_mass}" />
            <inertia ixx="0.00013978" ixy="0.0"  ixz="0.0" iyy="0.00025806" iyz="0.0" izz="0.00013978" />
        </inertial>
        <mu>5.0</mu>
    </link>
    <joint name="rr_castor_to_chassis" type="continuous">
        <parent link="rr_castor_housing_link"/>
        <child link="rr_castor_link"/>
        <axis xyz="0 1 0"/>
        <origin xyz="-0.031 0 -0.027" rpy="0 0 0"/>
    </joint>

  <!-- IMU -->
<!--
  <link name="imu_link">
    <visual>
      <geometry>
        <box size="0.1 0.1 0.1"/>
      </geometry>
    </visual>

    <collision>
      <geometry>
        <box size="0.1 0.1 0.1"/>
      </geometry>
    </collision>

    <xacro:box_inertia m="0.001" w="0.1" d="0.1" h="0.1"/>
  </link>
  <gazebo reference="imu_link">
    <sensor name="imu_sensor" type="imu">
      <ignition_frame_id>imu_link</ignition_frame_id>
      <plugin filename="ignition-gazebo-imu-system" name="ignition::gazebo::systems::Imu">
      </plugin>

      <topic>imu</topic>
      <always_on>true</always_on>
      <update_rate>100</update_rate>
      <visualize>true</visualize>
      <imu>
        <angular_velocity>
          <x>
            <noise type="gaussian">
              <mean>0.0</mean>
              <stddev>2e-4</stddev>
              <bias_mean>0.0000075</bias_mean>
              <bias_stddev>0.0000008</bias_stddev>
            </noise>
          </x>
          <y>
            <noise type="gaussian">
              <mean>0.0</mean>
              <stddev>2e-4</stddev>
              <bias_mean>0.0000075</bias_mean>
              <bias_stddev>0.0000008</bias_stddev>
            </noise>
          </y>
          <z>
            <noise type="gaussian">
              <mean>0.0</mean>
              <stddev>2e-4</stddev>
              <bias_mean>0.0000075</bias_mean>
              <bias_stddev>0.0000008</bias_stddev>
            </noise>
          </z>
        </angular_velocity>
        <linear_acceleration>
          <x>
            <noise type="gaussian">
              <mean>0.0</mean>
              <stddev>1.7e-2</stddev>
              <bias_mean>0.1</bias_mean>
              <bias_stddev>0.001</bias_stddev>
            </noise>
          </x>
          <y>
            <noise type="gaussian">
              <mean>0.0</mean>
              <stddev>1.7e-2</stddev>
              <bias_mean>0.1</bias_mean>
              <bias_stddev>0.001</bias_stddev>
            </noise>
          </y>
          <z>
            <noise type="gaussian">
              <mean>0.0</mean>
              <stddev>1.7e-2</stddev>
              <bias_mean>0.1</bias_mean>
              <bias_stddev>0.001</bias_stddev>
            </noise>
          </z>
        </linear_acceleration>
      </imu>
    </sensor>
  </gazebo>
  <joint name="imu_joint" type="fixed">
    <parent link="base_link"/>
    <child link="imu_link"/>
    <origin xyz="0 0 0.1"/>
  </joint>
-->

  <!-- Control -->
  <ros2_control name="IgnitionSystem" type="system">
    <hardware>
      <plugin>ign_ros2_control/IgnitionSystem</plugin>
    </hardware>
    <joint name="fl_wheel_to_chassis">
      <command_interface name="velocity">
        <param name="min">-1</param>
        <param name="max">1</param>
      </command_interface>
      <state_interface name="position"/>
      <state_interface name="velocity"/>
    </joint>
    <joint name="fr_wheel_to_chassis">
      <command_interface name="velocity">
        <param name="min">-1</param>
        <param name="max">1</param>
      </command_interface>
      <state_interface name="position"/>
      <state_interface name="velocity"/>
    </joint>
  </ros2_control>
  <gazebo>
    <plugin filename="ign_ros2_control-system" name="ign_ros2_control::IgnitionROS2ControlPlugin">
      <parameters>$(find nav2_gazebo)/config/diff_drive_controller_velocity.yaml</parameters>
    </plugin>
  </gazebo>

  <!-- Lidar -->
  <link name="lidar_link">
    <inertial>
      <origin xyz="0 0 0" rpy="0 0 0"/>
      <mass value="0.125"/>
      <inertia ixx="0.001" ixy="0" ixz="0" iyy="0.001" iyz="0" izz="0.001" />
    </inertial>

    <collision>
      <origin xyz="0 0 0" rpy="0 0 0"/>
      <geometry>
        <cylinder radius="0.0508" length="0.055"/>
      </geometry>
    </collision>

    <visual>
      <origin xyz="0 0 0" rpy="0 0 0"/>
      <geometry>
        <cylinder radius="0.0508" length="0.055"/>
      </geometry>
      <material name="LightBlue">
        <color rgba="0.11 0.37 0.56 1.0"/>
      </material>
    </visual>
  </link>

  <joint name="lidar_joint" type="fixed">
    <parent link="base_link"/>
    <child link="lidar_link"/>
    <origin xyz="0 0 0.5" rpy="0 0 0"/>
  </joint>

  <gazebo reference="lidar_link">
    <sensor name="lidar" type="gpu_lidar">
      <ignition_frame_id>lidar_link</ignition_frame_id>
      <topic>scan</topic>
      <always_on>true</always_on>
      <visualize>true</visualize>
      <update_rate>5</update_rate>
      <ray>
        <scan>
          <horizontal>
            <samples>360</samples>
            <resolution>1.000000</resolution>
            <min_angle>0.000000</min_angle>
            <max_angle>6.280000</max_angle>
          </horizontal>
        </scan>
        <range>
          <min>0.120000</min>
          <max>20.0</max>
          <resolution>0.015000</resolution>
        </range>
        <noise>
          <type>gaussian</type>
          <mean>0.0</mean>
          <stddev>0.01</stddev>
        </noise>
      </ray>
    </sensor>
  </gazebo>
</robot>
